<?xml version="1.0"?>
<!-- created with Phobos 1.0.1 "Capricious Choutengan" -->
  <robot name="wally">

    <link name="link_camera">
      <inertial>
        <origin xyz="0 0 0" rpy="0 0 0"/>
        <mass value="1.0"/>
        <inertia ixx="288.5336" ixy="0" ixz="-1e-05" iyy="274.41498" iyz="0" izz="149.48827"/>
      </inertial>
      <visual name="camera">
        <origin xyz="0 0 0" rpy="0 -1.5708 0"/>
        <geometry>
          <mesh filename="..\meshes\dae\Cube.018.dae" scale="1.0 1.0 1.0"/>
        </geometry>
        <material name="black"/>
      </visual>
      <collision name="camera">
        <origin xyz="-0.05651 -0.0476 0.12457" rpy="0 -1.5708 0"/>
        <geometry>
          <mesh filename="..\meshes\dae\Cube.028.dae" scale="1.0 1.0 1.0"/>
        </geometry>
      </collision>
    </link>

    <link name="link_chassis">
      <inertial>
        <origin xyz="0 0 0" rpy="0 0 0"/>
        <mass value="1.0"/>
        <inertia ixx="2658.80078" ixy="-0.00068" ixz="0" iyy="4901.40967" iyz="0" izz="5801.34521"/>
      </inertial>
      <visual name="chassis">
        <origin xyz="0 0 0" rpy="0 0 3.14159"/>
        <geometry>
          <mesh filename="..\meshes\dae\Cube.023.dae" scale="1.0 1.0 1.0"/>
        </geometry>
        <material name="yellow"/>
      </visual>
      <collision name="chassis">
        <origin xyz="-0.08775 -0.613 0.10621" rpy="0 0 3.14159"/>
        <geometry>
          <mesh filename="..\meshes\dae\Cube.026.dae" scale="1.0 1.0 1.0"/>
        </geometry>
      </collision>
    </link>

    <link name="link_laser">
      <inertial>
        <origin xyz="0 0 0" rpy="0 0 0"/>
        <mass value="1.0"/>
        <inertia ixx="297.87347" ixy="0" ixz="0" iyy="297.87271" iyz="0" izz="224.89485"/>
      </inertial>
      <visual name="laser">
        <origin xyz="0 0 0" rpy="0 0 0"/>
        <geometry>
          <mesh filename="..\meshes\dae\Cube.019.dae" scale="1.0 1.0 1.0"/>
        </geometry>
        <material name="black"/>
      </visual>
      <collision name="laser">
        <origin xyz="0 0 -0.02138" rpy="0 0 0"/>
        <geometry>
          <mesh filename="..\meshes\dae\Cube.027.dae" scale="1.0 1.0 1.0"/>
        </geometry>
      </collision>
    </link>

    <link name="link_wheel_caster">
      <inertial>
        <origin xyz="0 0 0" rpy="0 0 0"/>
        <mass value="1.0"/>
        <inertia ixx="59.09788" ixy="0" ixz="0" iyy="40.71418" iyz="0" izz="77.59837"/>
      </inertial>
      <visual name="wheel_caster">
        <origin xyz="0 0 0" rpy="0 0 0"/>
        <geometry>
          <mesh filename="..\meshes\dae\Cube.020.dae" scale="1.0 1.0 1.0"/>
        </geometry>
        <material name="black"/>
      </visual>
    </link>

    <link name="link_wheel_left">
      <inertial>
        <origin xyz="0 0 0" rpy="0 0 0"/>
        <mass value="1.0"/>
        <inertia ixx="289.20636" ixy="0" ixz="0" iyy="506.04105" iyz="-2e-05" izz="289.19714"/>
      </inertial>
      <visual name="wheel_left">
        <origin xyz="0 0 0" rpy="1.5708 0 0"/>
        <geometry>
          <mesh filename="..\meshes\dae\Cube.022.dae" scale="1.0 1.0 1.0"/>
        </geometry>
        <material name="yellow"/>
      </visual>
      <collision name="wheel_left">
        <origin xyz="0.01732 -0.02453 -0.10548" rpy="1.5708 0 0"/>
        <geometry>
          <mesh filename="..\meshes\dae\Cube.025.dae" scale="1.0 1.0 1.0"/>
        </geometry>
      </collision>
    </link>

    <link name="link_wheel_right">
      <inertial>
        <origin xyz="0 0 0" rpy="0 0 0"/>
        <mass value="1.0"/>
        <inertia ixx="289.20636" ixy="0" ixz="0" iyy="506.04105" iyz="2e-05" izz="289.19717"/>
      </inertial>
      <visual name="wheel_right">
        <origin xyz="0 0 0" rpy="-1.5708 0 0"/>
        <geometry>
          <mesh filename="..\meshes\dae\Cube.017.dae" scale="1.0 1.0 1.0"/>
        </geometry>
        <material name="yellow"/>
      </visual>
      <collision name="wheel_right">
        <origin xyz="0.01732 0.02454 -2.55418" rpy="-1.5708 0 0"/>
        <geometry>
          <mesh filename="..\meshes\dae\Cube.024.dae" scale="1.0 1.0 1.0"/>
        </geometry>
      </collision>
    </link>

    <joint name="link_camera" type="fixed">
      <origin xyz="-99.50021 -0.66059 75.61109" rpy="-3.14159 1.5708 0"/>
      <parent link="link_chassis"/>
      <child link="link_camera"/>
    </joint>

    <joint name="link_laser" type="fixed">
      <origin xyz="13.13231 -0.613 104.50001" rpy="0 0 3.14159"/>
      <parent link="link_chassis"/>
      <child link="link_laser"/>
    </joint>

    <joint name="link_wheel_caster" type="fixed">
      <origin xyz="98.95988 -0.61332 -7.88988" rpy="0 0 3.14159"/>
      <parent link="link_chassis"/>
      <child link="link_wheel_caster"/>
    </joint>

    <joint name="link_wheel_left" type="revolute">
      <origin xyz="-6.02121 -77.0348 16.15401" rpy="-1.5708 0 3.14159"/>
      <parent link="link_chassis"/>
      <child link="link_wheel_left"/>
      <axis xyz="0 0 1.0"/>
      <limit lower="-3.14" upper="3.14" effort="0" velocity="0"/>
    </joint>

    <joint name="link_wheel_right" type="revolute">
      <origin xyz="-6.0212 76.51163 16.154" rpy="1.5708 0 3.14159"/>
      <parent link="link_chassis"/>
      <child link="link_wheel_right"/>
      <axis xyz="0 0 1.0"/>
      <limit lower="-3.14" upper="3.14" effort="0" velocity="0"/>
    </joint>

    <material name="black">
      <color rgba="0.8 0.8 0.8 1.0"/>
    </material>

    <material name="yellow">
      <color rgba="0.8 0.8 0.8 1.0"/>
    </material>

  </robot>
