<?xml version="1.0"?>
<!-- created with Phobos 1.0.1 "Capricious Choutengan" -->
  <robot name="wally">

    <link name="link_camera">
      <inertial>
        <origin xyz="0 0 0" rpy="0 0 0"/>
        <mass value="1.0"/>
        <inertia ixx="288.5336" ixy="0" ixz="0" iyy="274.41498" iyz="0" izz="149.48827"/>
      </inertial>
      <visual name="camera">
        <origin xyz="0 0 0" rpy="0 0 0"/>
        <geometry>
          <mesh filename="file://$(find wally)/meshes/stl/Cube.018.stl" scale="1.0 1.0 1.0"/>
        </geometry>
        <material name="black"/>
      </visual>
      <collision name="camera">
        <origin xyz="0.00012 -5e-05 6e-05" rpy="0 0 0"/>
        <geometry>
          <mesh filename="file://$(find wally)/meshes/stl/Cube.028.stl" scale="1.0 1.0 1.0"/>
        </geometry>
      </collision>
    </link>

    <link name="link_chassis">
      <inertial>
        <origin xyz="0 0 0" rpy="0 0 0"/>
        <mass value="1.0"/>
        <inertia ixx="2658.80078" ixy="0" ixz="0" iyy="4901.40967" iyz="0" izz="5801.34521"/>
      </inertial>
      <visual name="chassis">
        <origin xyz="0 0 0" rpy="0 0 0"/>
        <geometry>
          <mesh filename="file://$(find wally)/meshes/stl/Cube.023.stl" scale="1.0 1.0 1.0"/>
        </geometry>
        <material name="yellow"/>
      </visual>
      <collision name="chassis">
        <origin xyz="9e-05 0.00061 0.00011" rpy="0 0 0"/>
        <geometry>
          <mesh filename="file://$(find wally)/meshes/stl/Cube.026.stl" scale="1.0 1.0 1.0"/>
        </geometry>
      </collision>
    </link>

    <link name="link_laser">
      <inertial>
        <origin xyz="0 0 0" rpy="0 0 0"/>
        <mass value="1.0"/>
        <inertia ixx="297.87347" ixy="0" ixz="0" iyy="297.87271" iyz="0" izz="224.89485"/>
      </inertial>
      <visual name="laser">
        <origin xyz="0 0 0" rpy="0 0 0"/>
        <geometry>
          <mesh filename="file://$(find wally)/meshes/stl/Cube.019.stl" scale="1.0 1.0 1.0"/>
        </geometry>
        <material name="black"/>
      </visual>
      <collision name="laser">
        <origin xyz="0 0 -2e-05" rpy="0 0 0"/>
        <geometry>
          <mesh filename="file://$(find wally)/meshes/stl/Cube.027.stl" scale="1.0 1.0 1.0"/>
        </geometry>
      </collision>
    </link>

    <link name="link_wheel_caster">
      <inertial>
        <origin xyz="0 0 0" rpy="0 0 0"/>
        <mass value="1.0"/>
        <inertia ixx="59.09788" ixy="0" ixz="0" iyy="40.71418" iyz="0" izz="77.59837"/>
      </inertial>
      <visual name="wheel_caster">
        <origin xyz="0 0 0" rpy="0 0 0"/>
        <geometry>
          <mesh filename="file://$(find wally)/meshes/stl/Cube.020.stl" scale="1.0 1.0 1.0"/>
        </geometry>
        <material name="black"/>
      </visual>
    </link>

    <link name="link_wheel_left">
      <inertial>
        <origin xyz="0 0 0" rpy="0 0 0"/>
        <mass value="1.0"/>
        <inertia ixx="289.20636" ixy="0" ixz="0" iyy="506.04105" iyz="0" izz="289.19714"/>
      </inertial>
      <visual name="wheel_left">
        <origin xyz="0 0 0" rpy="0 0 0"/>
        <geometry>
          <mesh filename="file://$(find wally)/meshes/stl/Cube.022.stl" scale="1.0 1.0 1.0"/>
        </geometry>
        <material name="yellow"/>
      </visual>
      <collision name="wheel_left">
        <origin xyz="2e-05 -0.00011 2e-05" rpy="0 0 0"/>
        <geometry>
          <mesh filename="file://$(find wally)/meshes/stl/Cube.025.stl" scale="1.0 1.0 1.0"/>
        </geometry>
      </collision>
    </link>

    <link name="link_wheel_right">
      <inertial>
        <origin xyz="0 0 0" rpy="0 0 0"/>
        <mass value="1.0"/>
        <inertia ixx="289.20636" ixy="0" ixz="0" iyy="506.04105" iyz="0" izz="289.19717"/>
      </inertial>
      <visual name="wheel_right">
        <origin xyz="0 0 0" rpy="0 0 0"/>
        <geometry>
          <mesh filename="file://$(find wally)/meshes/stl/Cube.017.stl" scale="1.0 1.0 1.0"/>
        </geometry>
        <material name="yellow"/>
      </visual>
      <collision name="wheel_right">
        <origin xyz="2e-05 0.00255 2e-05" rpy="0 0 0"/>
        <geometry>
          <mesh filename="file://$(find wally)/meshes/stl/Cube.024.stl" scale="1.0 1.0 1.0"/>
        </geometry>
      </collision>
    </link>

    <joint name="link_camera" type="fixed">
      <origin xyz="0.0995 0.00066 0.07561" rpy="0 0 0"/>
      <parent link="link_chassis"/>
      <child link="link_camera"/>
    </joint>

    <joint name="link_laser" type="fixed">
      <origin xyz="-0.01313 0.00061 0.1045" rpy="0 0 0"/>
      <parent link="link_chassis"/>
      <child link="link_laser"/>
    </joint>

    <joint name="link_wheel_caster" type="fixed">
      <origin xyz="-0.09896 0.00061 -0.00789" rpy="0 0 0"/>
      <parent link="link_chassis"/>
      <child link="link_wheel_caster"/>
    </joint>

    <joint name="link_wheel_left" type="revolute">
      <origin xyz="0.00602 0.07703 0.01615" rpy="0 0 0"/>
      <parent link="link_chassis"/>
      <child link="link_wheel_left"/>
      <axis xyz="0 1.0 0"/>
      <limit lower="-3.14" upper="3.14" effort="0" velocity="0"/>
    </joint>

    <joint name="link_wheel_right" type="revolute">
      <origin xyz="0.00602 -0.07651 0.01615" rpy="0 0 0"/>
      <parent link="link_chassis"/>
      <child link="link_wheel_right"/>
      <axis xyz="0 -1.0 0"/>
      <limit lower="-3.14" upper="3.14" effort="0" velocity="0"/>
    </joint>

    <material name="black">
      <color rgba="0.8 0.8 0.8 1.0"/>
    </material>

    <material name="yellow">
      <color rgba="0.8 0.8 0.8 1.0"/>
    </material>

  </robot>